<mujoco>
	<option gravity="0 0 -10"/>
	<option timestep="0.001" iterations="150"/>
	<worldbody>
		<light diffuse=".5 .5 .5" pos="0 0 12" dir="0 0 -1"/>
		
<!--Than-->
<body pos="0 0 1">
			
	
	<!--Chan, damping="0.00183"-->
	<!--Thanh dam xoan 1-->
	<body pos="-0.11 -0.06 0.0035">

		<geom type="box" density="1200" size=".0083 .01 .0015" rgba="0 1 0 1"/>

		
			<body pos="0 -.0201 0" euler=" 0 90 0">
				<!-- Uon quanh Z -->
				<joint type="hinge" name = "X2" axis="0 0 -1" stiffness="1.062072" damping="2.21209" springref="0" frictionloss="0" pos="0 .01 0"/>
				<!-- Xoan quanh Y -->
				<joint type="hinge"  name="Y2" axis="0 -1 0" stiffness="0.0024" damping="0.0000183" springref="0" frictionloss="0" pos="0 .01 0" />

				<geom type="box" density="1200" size=".0083 .01 .0015" rgba="0 1 0 1"/>
				<!--Ban chan-->
				
				<body name ="O" pos=" .035  -.0085 -0.00" euler=" 90 90 0">
					<geom type="box" density="1240" size=".0017 .0025 .0425" pos="-.0034 0 0" rgba="1 0 1 1" friction="0.6 0.002 0.002" solref="0.003 1.2" solimp="0.9 0.95 0.001"/>
					<geom type="box" density="1240" size=".0017 .0025 .0425" pos="0 0 0" rgba="1 0 0 1" friction="0.6 0.002 0.002" solref="0.003 1.2" solimp="0.9 0.95 0.001"/>
					<geom type="box" density="1240" size=".0017 .0025 .0425" pos=".0034 0 0" rgba="1 1 0 1" friction="0.6 0.002 0.002" solref="0.003 1.2" solimp="0.9 0.95 0.001"/>

					<site name="S1" rgba="0 1 1 .2"/>
						<!--sensor-->
				</body>


			</body>
		</body>



	

</body>
		
		

	</worldbody>


	<actuator>
		<motor joint="Y2" gear="0.1"/>
	</actuator>

	<sensor>
		<framequat objtype="site" objname="S1" name="framequat_S1"/>
	</sensor>
	

</mujoco>