<!-- friction mac dinh: friction="0.6 0.002 0.002"-->
	<mujoco>
	<option gravity="0 0 -25" timestep="0.001" iterations="150"/>
	<asset>
		<material name="floor" texture="check1" texrepeat="2 2" texuniform="true"/>
		<texture name="check1" builtin="checker" type="2d" width="256" height="256" rgb1="1 1 1" rgb2="0 0 0"/>

		<material name="object" texture="check2" texrepeat="5 5" texuniform="true"/>
		<texture name="check2" builtin="checker" type="2d" width="256" height="256" rgb1="0 0 1" rgb2="0 1 0"/>
	</asset>
	<worldbody>
		<light diffuse=".5 .5 .5" pos="0 0 12" dir="0 0 -1"/>
		<geom name="floor" size="25 25 .05" type="plane" material="floor" condim="3" friction="0.6 0.002 0.002"/>
<!--Than-->
<body pos="0 0 .075">
			<joint type="free"/>
			<geom type="box" mass="0.016" contype="0" conaffinity="0" rgba="0 1 1 .2" size="0.11 0.06 .00175"/> <!--tấm thân sandwich carbon (plate): vật liệu nhẹ (carbon + lõi balsa)-->
	<!--2 rotor-->
	<body pos="0 0 0">
	<geom type="cylinder" mass=".1" size=".03 .015" contype="0" conaffinity="0" rgba="0 1 1 .5"/> <!--cụm roto là tổng hợp của nhiều thứ liền kề, tong 0.7 [1]-->


		
		<body pos="0 0 0">
	
			

		</body>
	
</body>
	
	<!--Chan-->
	<!--Thanh dam xoan 1-->
	<body pos="-0.11 -0.06 0.0035">
		<!-- Uon quanh X -->
		<joint type="hinge" name = "X10" axis="-1 0 0" stiffness="1.062072" damping="2.21209" springref="0" pos="0 .01 0"/>
		<geom type="box" density="1200" size=".0083 .01 .0015" rgba="0 1 0 1"/>

		<body pos="0 -.02 0" euler=" 0 45 0">
			<!-- Uon quanh X -->
			<joint type="hinge" name = "X11" axis="-1 0 0" stiffness="1.062072" damping="2.21209" springref="0" pos="0 .01 0"/>
			<!-- Xoan quanh Y -->
			<joint type="hinge" name="Y11" axis="0 -1 0" stiffness="0.0024" damping="0.00183" springref="0" pos="0 .01 0"/>

			<geom type="box" density="1200" size=".0083 .01 .0015" rgba="0 1 0 1"/>

			<body pos="0 -.02 0" euler=" 0 45 0">
				<!-- Uon quanh X -->
				<joint type="hinge" name = "X12" axis="-1 0 0" stiffness="1.062072" damping="2.21209" springref="0" pos="0 .01 0"/>
				<!-- Xoan quanh Y -->
				<joint type="hinge" name="Y12" axis="0 -1 0" stiffness="0.0024" damping="0.00183" springref="0" pos="0 .01 0" />

				<geom type="box" density="1200" size=".0083 .01 .0015" rgba="0 1 0 1"/>
				<!--Ban chan-->

				<body pos=".035 -.0085 -0.00" euler="90 90 0">

					<geom type="box" density="1240" size=".0017 .0025 .0425" pos="-.0034 0 0" rgba="1 0 1 1" friction="0.6 0.002 0.002" solref="0.003 1.2" solimp="0.9 0.95 0.001"/>
					<geom type="box" density="1240" size=".0017 .0025 .0425" pos="0 0 0" rgba="1 0 0 1" friction="0.6 0.002 0.002" solref="0.003 1.2" solimp="0.9 0.95 0.001"/>
					<geom type="box" density="1240" size=".0017 .0025 .0425" pos=".0034 0 0" rgba="1 1 0 1" friction="0.6 0.002 0.002" solref="0.003 1.2" solimp="0.9 0.95 0.001"/>

					<!-- sensor -->
					<site name="S1" pos="0 0 0.0425" rgba="0 1 1 1"/>

				</body>

			</body>
		</body>
	</body>


	<!--Thanh dam xoan 2-->
	<body pos="0.11 0.06 0.0035" euler="0 0 180">
		<!-- Uon quanh X -->
		<joint type="hinge" name = "X20" axis="-1 0 0" stiffness="1.062072" damping="2.21209" springref="0" pos="0 .01 0"/>
		

		
		<geom type="box" density="1200" size=".0083 .01 .0015" rgba="0 1 0 1"/>

		<body pos="0 -.02 0" euler=" 0 -45 0">
			<!-- Uon quanh X -->
			<joint type="hinge" name = "X21" axis="-1 0 0" stiffness="1.062072" damping="2.21209" springref="0" pos="0 .02 0"/>
			<!-- Xoan quanh Y -->
			<joint type="hinge" name = "Y21" axis="0 -1 0" stiffness="0.0024" damping="0.00183" springref="0" pos="0 .02 0" />

			<geom type="box" density="1200" size=".0083 .01 .0015" rgba="0 1 0 1"/>

			<body pos="0 -.02 0" euler=" 0 -45 0">
				<!-- Uon quanh X -->
				<joint type="hinge" name = "X22" axis="-1 0 0" stiffness="1.062072" damping="2.21209" springref="0" pos="0 .02 0"/>
				<!-- Xoan quanh Y -->
				<joint type="hinge" name = "Y22" axis="0 -1 0" stiffness="0.0024" damping="0.00183" springref="0" pos="0 .02 0" />

				
				<geom type="box" density="1200" size=".0083 .01 .0015" rgba="0 1 0 1"/>
				<!--Ban chan-->
				<body pos=" -.035 -.0085 -0.00" euler="90 90 0">
					<geom type="box" density="1240" size=".0017 .0025 .0425" pos="-.0034 0 0" rgba="1 0 1 1" friction="0.6 0.002 0.002" solref="0.003 1.2" solimp="0.9 0.95 0.001"/>
					<geom type="box" density="1240" size=".0017 .0025 .0425" pos="0 0 0" rgba="1 0 0 1" friction="0.6 0.002 0.002" solref="0.003 1.2" solimp="0.9 0.95 0.001"/>
					<geom type="box" density="1240" size=".0017 .0025 .0425" pos=".0034 0 0" rgba="1 1 0 1" friction="0.6 0.002 0.002" solref="0.003 1.2" solimp="0.9 0.95 0.001"/>
					<site name="S2" pos="0 0 -0.0425" rgba="0 1 0 1"/>
				</body>

			</body>
		</body>
	</body>

	<!--Thanh dam xoan 3-->
	<body pos="0.11 -0.06 0.0035">
		<!-- Uon quanh X -->
		<joint type="hinge" name = "X30" axis="-1 0 0" stiffness="1.062072" damping="2.21209" springref="0" pos="0 .02 0"/>
		

		
		<geom type="box" density="1200" size=".0083 .01 .0015" rgba="0 1 0 1"/>

		<body pos="0 -.02 0" euler=" 0 45 0">
			<!-- Uon quanh X -->
			<joint type="hinge" name = "X31" axis="-1 0 0" stiffness="1.062072" damping="2.21209" springref="0" pos="0 .02 0"/>
			<!-- Xoan quanh Y -->
			<joint type="hinge" name = "Y31" axis="0 -1 0" stiffness="0.0024" damping="0.00183" springref="0" pos="0 .02 0" />

			
			<geom type="box" density="1200" size=".0083 .01 .0015" rgba="0 1 0 1"/>

			<body pos="0 -.02 0" euler=" 0 45 0">
				<!-- Uon quanh X -->
				<joint type="hinge"  name = "X32" axis="-1 0 0" stiffness="1.062072" damping="2.21209" springref="0" pos="0 .02 0"/>
				<!-- Xoan quanh Y -->
				<joint type="hinge" name = "Y32" axis="0 -1 0" stiffness="0.0024" damping="0.00183" springref="0" pos="0 .02 0" />

				<geom type="box" density="1200" size=".0083 .01 .0015" rgba="0 1 0 1"/>

				<!--Ban chan-->
				<body pos=" .035 -.0085 -0.00" euler="90 90 0">
					<geom type="box" density="1240" size=".0017 .0025 .0425" pos="-.0034 0 0" rgba="1 0 1 1" friction="0.6 0.002 0.002" solref="0.003 1.2" solimp="0.9 0.95 0.001"/>
					<geom type="box" density="1240" size=".0017 .0025 .0425" pos="0 0 0"    rgba="1 0 0 1" friction="0.6 0.002 0.002" solref="0.003 1.2" solimp="0.9 0.95 0.001"/>
					<geom type="box" density="1240" size=".0017 .0025 .0425" pos=".0034 0 0" rgba="1 1 0 1" friction="0.6 0.002 0.002" solref="0.003 1.2" solimp="0.9 0.95 0.001"/>
					<site name="S3" pos="0 0 0.0425" rgba="0 0 1 1"/>
				</body>

			</body>
		</body>
	</body>

	<!--Thanh dam xoan 4-->
	<body pos="-0.11 0.06 0.0035" euler="0 0 180">
		<!-- Uon quanh X -->
		<joint type="hinge"  name = "X40" axis="-1 0 0" stiffness="1.062072" damping="2.21209" springref="0" pos="0 .02 0"/>
		

		<geom type="box" density="1200" size=".0083 .01 .0015" rgba="0 1 0 1"/>

		<body pos="0 -.02 0" euler=" 0 -45 0">
			<!-- Uon quanh X -->
			<joint type="hinge" name = "X41" axis="-1 0 0" stiffness="1.062072" damping="2.21209" springref="0" pos="0 .02 0"/>
			<!-- Xoan quanh Y -->
			<joint type="hinge" name = "Y41" axis="0 -1 0" stiffness="0.0024" damping="0.00183" springref="0" pos="0 .02 0" />

			<geom type="box" density="1200" size=".0083 .01 .0015" rgba="0 1 0 1"/>

			<body pos="0 -.02 0" euler=" 0 -45 0">
				<!-- Uon quanh X -->
				<joint type="hinge" name = "X42" axis="-1 0 0" stiffness="1.062072" damping="2.21209" springref="0" pos="0 .02 0"/>
				<!-- Xoan quanh Y -->
				<joint type="hinge" name = "Y42" axis="0 -1 0" stiffness="0.0024" damping="0.00183" springref="0" pos="0 .02 0" />

				<geom type="box" density="1200" size=".0083 .01 .0015" rgba="0 1 0 1"/>
				<!--Ban chan-->
				<body pos=" -.035 -.0085 -0.00" euler="90 90 0">
					<geom type="box" density="1240" size=".0017 .0025 .0425" pos="-.0034 0 0" rgba="1 0 1 1" friction="0.6 0.002 0.002" solref="0.003 1.2" solimp="0.9 0.95 0.001"/>
					<geom type="box" density="1240" size=".0017 .0025 .0425" pos="0 0 0"    rgba="1 0 0 1" friction="0.6 0.002 0.002" solref="0.003 1.2" solimp="0.9 0.95 0.001"/>
					<geom type="box" density="1240" size=".0017 .0025 .0425" pos=".0034 0 0" rgba="1 1 0 1" friction="0.6 0.002 0.002" solref="0.003 1.2" solimp="0.9 0.95 0.001"/>
					<site name="S4" pos="0 0 -0.0425" rgba="1 1 1 1"/>
				</body>

			</body>
		</body>
	</body>


</body>
		
		

	</worldbody>


	
	<sensor>
		<force name="Site1" site="S1"/>
		<force name="Site2" site="S2"/>
		<force name="Site3" site="S3"/>
		<force name="Site4" site="S4"/>
	</sensor>
	

</mujoco>